Workbook

Sheet Параметры
A1: ЕВА — Финансовая модель
A2: Входные параметры (изменяйте синие ячейки)
A5: ИНВЕСТИЦИИ И СРОКИ
A6: Объём инвестиций, RUB | B6: 5000000 | C6: Общий бюджет
A7: Горизонт модели, мес | B7: 24
A9: ЦЕНООБРАЗОВАНИЕ
A10: Цена EVA+ месяц, RUB | B10: 1990 | C10: Основной тариф
A11: Цена EVA+ год, RUB | B11: 9990 | C11: Годовая подписка
A12: Доля годовых подписок, % | B12: 30 | C12: % на годовом тарифе
A14: ПРИВЛЕЧЕНИЕ
A15: CAC, RUB | B15: 120 | C15: Средний по каналам
A16: Органический трафик, % | B16: 40 | C16: Telegram, ASO, реферальная
A17: Новые пользователи мес 1 | B17: 200 | C17: Старт
A18: Рост новых / мес, % | B18: 15 | C18: Месячный рост привлечения
A19: Макс. новых / мес | B19: 5000 | C19: Потолок
A21: КОНВЕРСИЯ И УДЕРЖАНИЕ
A22: Конверсия Free - EVA+, % | B22: 5 | C22: Бенчмарк: 3-8%
A23: Churn EVA+ месячный, % | B23: 8 | C23: Бенчмарк: 6-12%
A25: ИНВЕСТИЦИИ — РАСПРЕДЕЛЕНИЕ
A26: 3D-моделирование + дизайн | B26: 1500000 | C26: 30 состояний мира
A27: Мобильная разработка | B27: 1350000 | C27: React Native iOS+Android
A28: Миграция на РФ-хостинг | B28: 592000 | C28: Workers-Node.js, Auth, DB
A29: Маркетинг (из инвестиций) | B29: 810000 | C29: ASO, таргет, influencers
A30: Резерв | B30: 298000 | C30: Непредвиденные
A32: ОПЕРАЦИОННЫЕ РАСХОДЫ
A33: Разработка мес 1-6 | B33: 200000 | C33: RUB/мес
A34: Разработка мес 7-12 | B34: 120000
A35: Разработка мес 13+ | B35: 100000
A36: Маркетинг мес 1-6 | B36: 120000
A37: Маркетинг мес 7-12 | B37: 150000
A38: Маркетинг мес 13+ | B38: 180000
A39: Инфраструктура РФ мес 1-6 | B39: 8000 | C39: VPS+PG+S3+CDN
A40: Инфраструктура РФ мес 7-12 | B40: 19500
A41: Инфраструктура РФ мес 13+ | B41: 35000
A42: Контент мес 1-6 | B42: 50000 | C42: Психолог, копирайт
A43: Контент мес 7-12 | B43: 30000
A44: Контент мес 13+ | B44: 20000
A45: App Store комиссия, % | B45: 30
A46: Доля iOS-подписок, % | B46: 40
A47: Telegram-бот доработка/мес | B47: 15000 | C47: С месяца 3
...

Sheet P&L помесячный
A1: P&L помесячный (24 месяца)
A3: Показатель | B3: Мес 1 | C3: Мес 2 | D3: Мес 3 | E3: Мес 4 | F3: Мес 5 | G3: Мес 6 | H3: Мес 7 | I3: Мес 8 | J3: Мес 9 | K3: Мес 10 | L3: Мес 11 | M3: Мес 12 | N3: Мес 13 | O3: Мес 14 | P3: Мес 15 | Q3: Мес 16 | R3: Мес 17 | S3: Мес 18 | T3: Мес 19 | U3: Мес 20 | V3: Мес 21 | W3: Мес 22 | X3: Мес 23 | Y3: Мес 24
A4: ПОЛЬЗОВАТЕЛИ
A5: Новые пользователи | B5: =MIN('Параметры'!B17*(1+'Параметры'!B18/100)^(1-1),'Параметры'!B19) | C5: =MIN('Параметры'!B17*(1+'Параметры'!B18/100)^(2-1),'Параметры'!B19) | D5: =MIN('Параметры'!B17*(1+'Параметры'!B18/100)^(3-1),'Параметры'!B19) | E5: =MIN('Параметры'!B17*(1+'Параметры'!B18/100)^(4-1),'Параметры'!B19) | F5: =MIN('Параметры'!B17*(1+'Параметры'!B18/100)^(5-1),'Параметры'!B19) | G5: =MIN('Параметры'!B17*(1+'Параметры'!B18/100)^(6-1),'Параметры'!B19) | H5: =MIN('Параметры'!B17*(1+'Параметры'!B18/100)^(7-1),'Параметры'!B19) | I5: =MIN('Параметры'!B17*(1+'Параметры'!B18/100)^(8-1),'Параметры'!B19) | J5: =MIN('Параметры'!B17*(1+'Параметры'!B18/100)^(9-1),'Параметры'!B19) | K5: =MIN('Параметры'!B17*(1+'Параметры'!B18/100)^(10-1),'Параметры'!B19) | L5: =MIN('Параметры'!B17*(1+'Параметры'!B18/100)^(11-1),'Параметры'!B19) | M5: =MIN('Параметры'!B17*(1+'Параметры'!B18/100)^(12-1),'Параметры'!B19) | N5: =MIN('Параметры'!B17*(1+'Параметры'!B18/100)^(13-1),'Параметры'!B19) | O5: =MIN('Параметры'!B17*(1+'Параметры'!B18/100)^(14-1),'Параметры'!B19) | P5: =MIN('Параметры'!B17*(1+'Параметры'!B18/100)^(15-1),'Параметры'!B19) | Q5: =MIN('Параметры'!B17*(1+'Параметры'!B18/100)^(16-1),'Параметры'!B19) | R5: =MIN('Параметры'!B17*(1+'Параметры'!B18/100)^(17-1),'Параметры'!B19) | S5: =MIN('Параметры'!B17*(1+'Параметры'!B18/100)^(18-1),'Параметры'!B19) | T5: =MIN('Параметры'!B17*(1+'Параметры'!B18/100)^(19-1),'Параметры'!B19) | U5: =MIN('Параметры'!B17*(1+'Параметры'!B18/100)^(20-1),'Параметры'!B19) | V5: =MIN('Параметры'!B17*(1+'Параметры'!B18/100)^(21-1),'Параметры'!B19) | W5: =MIN('Параметры'!B17*(1+'Параметры'!B18/100)^(22-1),'Параметры'!B19) | X5: =MIN('Параметры'!B17*(1+'Параметры'!B18/100)^(23-1),'Параметры'!B19) | Y5: =MIN('Параметры'!B17*(1+'Параметры'!B18/100)^(24-1),'Параметры'!B19)
A6: Всего (накопл.) | B6: =B5 | C6: =B6+C5 | D6: =C6+D5 | E6: =D6+E5 | F6: =E6+F5 | G6: =F6+G5 | H6: =G6+H5 | I6: =H6+I5 | J6: =I6+J5 | ... Y6: =X6+Y5
A7: EVA+ подписчики | B7: =ROUND(B6*'Параметры'!B22/100,0) | C7: =ROUND(C6*'Параметры'!B22/100,0) | D7: =ROUND(D6*'Параметры'!B22/100,0) | E7: =ROUND(E6*'Параметры'!B22/100,0) | F7: =ROUND(F6*'Параметры'!B22/100,0) | G7: =ROUND(G6*'Параметры'!B22/100,0) | H7: =ROUND(H6*'Параметры'!B22/100,0) | I7: =ROUND(I6*'Параметры'!B22/100,0) | J7: =ROUND(J6*'Параметры'!B22/100,0) | K7: =ROUND(K6*'Параметры'!B22/100,0) | L7: =ROUND(L6*'Параметры'!B22/100,0) | M7: =ROUND(M6*'Параметры'!B22/100,0) | N7: =ROUND(N6*'Параметры'!B22/100,0) | O7: =ROUND(O6*'Параметры'!B22/100,0) | P7: =ROUND(P6*'Параметры'!B22/100,0) | Q7: =ROUND(Q6*'Параметры'!B22/100,0) | R7: =ROUND(R6*'Параметры'!B22/100,0) | S7: =ROUND(S6*'Параметры'!B22/100,0) | T7: =ROUND(T6*'Параметры'!B22/100,0) | U7: =ROUND(U6*'Параметры'!B22/100,0) | V7: =ROUND(V6*'Параметры'!B22/100,0) | W7: =ROUND(W6*'Параметры'!B22/100,0) | X7: =ROUND(X6*'Параметры'!B22/100,0) | Y7: =ROUND(Y6*'Параметры'!B22/100,0)
A9: ВЫРУЧКА
A10: ARPU средний | B10: ='Параметры'!B10*(1-'Параметры'!B12/100)+'Параметры'!B11/12*'Параметры'!B12/100 | C10: ='Параметры'!B10*(1-'Параметры'!B12/100)+'Параметры'!B11/12*'Параметры'!B12/100 | D10: ='Параметры'!B10*(1-'Параметры'!B12/100)+'Параметры'!B11/12*'Параметры'!B12/100 | E10: ='Параметры'!B10*(1-'Параметры'!B12/100)+'Параметры'!B11/12*'Параметры'!B12/100 | F10: ='Параметры'!B10*(1-'Параметры'!B12/100)+'Параметры'!B11/12*'Параметры'!B12/100 | G10: ='Параметры'!B10*(1-'Параметры'!B12/100)+'Параметры'!B11/12*'Параметры'!B12/100 | H10: ='Параметры'!B10*(1-'Параметры'!B12/100)+'Параметры'!B11/12*'Параметры'!B12/100 | I10: ='Параметры'!B10*(1-'Параметры'!B12/100)+'Параметры'!B11/12*'Параметры'!B12/100 | J10: ='Параметры'!B10*(1-'Параметры'!B12/100)+'Параметры'!B11/12*'Параметры'!B12/100 | K10: ='Параметры'!B10*(1-'Параметры'!B12/100)+'Параметры'!B11/12*'Параметры'!B12/100 | L10: ='Параметры'!B10*(1-'Параметры'!B12/100)+'Параметры'!B11/12*'Параметры'!B12/100 | M10: ='Параметры'!B10*(1-'Параметры'!B12/100)+'Параметры'!B11/12*'Параметры'!B12/100 | N10: ='Параметры'!B10*(1-'Параметры'!B12/100)+'Параметры'!B11/12*'Параметры'!B12/100 | O10: ='Параметры'!B10*(1-'Параметры'!B12/100)+'Параметры'!B11/12*'Параметры'!B12/100 | P10: ='Параметры'!B10*(1-'Параметры'!B12/100)+'Параметры'!B11/12*'Параметры'!B12/100 | Q10: ='Параметры'!B10*(1-'Параметры'!B12/100)+'Параметры'!B11/12*'Параметры'!B12/100 | R10: ='Параметры'!B10*(1-'Параметры'!B12/100)+'Параметры'!B11/12*'Параметры'!B12/100 | S10: ='Параметры'!B10*(1-'Параметры'!B12/100)+'Параметры'!B11/12*'Параметры'!B12/100 | T10: ='Параметры'!B10*(1-'Параметры'!B12/100)+'Параметры'!B11/12*'Параметры'!B12/100 | U10: ='Параметры'!B10*(1-'Параметры'!B12/100)+'Параметры'!B11/12*'Параметры'!B12/100 | V10: ='Параметры'!B10*(1-'Параметры'!B12/100)+'Параметры'!B11/12*'Параметры'!B12/100 | W10: ='Параметры'!B10*(1-'Параметры'!B12/100)+'Параметры'!B11/12*'Параметры'!B12/100 | X10: ='Параметры'!B10*(1-'Параметры'!B12/100)+'Параметры'!B11/12*'Параметры'!B12/100 | Y10: ='Параметры'!B10*(1-'Параметры'!B12/100)+'Параметры'!B11/12*'Параметры'!B12/100
A11: Подписки | B11: =B7*B10 | C11: =C7*C10 | D11: =D7*D10 | E11: =E7*E10 | F11: =F7*F10 | G11: =G7*G10 | H11: =H7*H10 | I11: =I7*I10 | ... Y11: =Y7*Y10
A12: Доп. сценарии | B12: =IF(1>='Параметры'!B50,'Параметры'!B51,0) | C12: =IF(2>='Параметры'!B50,'Параметры'!B51,0) | D12: =IF(3>='Параметры'!B50,'Параметры'!B51,0) | E12: =IF(4>='Параметры'!B50,'Параметры'!B51,0) | F12: =IF(5>='Параметры'!B50,'Параметры'!B51,0) | G12: =IF(6>='Параметры'!B50,'Параметры'!B51,0) | H12: =IF(7>='Параметры'!B50,'Параметры'!B51,0) | I12: =IF(8>='Параметры'!B50,'Параметры'!B51,0) | J12: =IF(9>='Параметры'!B50,'Параметры'!B51,0) | K12: =IF(10>='Параметры'!B50,'Параметры'!B51,0) | L12: =IF(11>='Параметры'!B50,'Параметры'!B51,0) | M12: =IF(12>='Параметры'!B50,'Параметры'!B51,0) | N12: =IF(13>='Параметры'!B50,'Параметры'!B51,0) | O12: =IF(14>='Параметры'!B50,'Параметры'!B51,0) | P12: =IF(15>='Параметры'!B50,'Параметры'!B51,0) | Q12: =IF(16>='Параметры'!B50,'Параметры'!B51,0) | R12: =IF(17>='Параметры'!B50,'Параметры'!B51,0) | S12: =IF(18>='Параметры'!B50,'Параметры'!B51,0) | T12: =IF(19>='Параметры'!B50,'Параметры'!B51,0) | U12: =IF(20>='Параметры'!B50,'Параметры'!B51,0) | V12: =IF(21>='Параметры'!B50,'Параметры'!B51,0) | W12: =IF(22>='Параметры'!B50,'Параметры'!B51,0) | X12: =IF(23>='Параметры'!B50,'Параметры'!B51,0) | Y12: =IF(24>='Параметры'!B50,'Параметры'!B51,0)
A13: Персональные маршруты | B13: =IF(1>='Параметры'!B52,'Параметры'!B53,0) | C13: =IF(2>='Параметры'!B52,'Параметры'!B53,0) | D13: =IF(3>='Параметры'!B52,'Параметры'!B53,0) | E13: =IF(4>='Параметры'!B52,'Параметры'!B53,0) | F13: =IF(5>='Параметры'!B52,'Параметры'!B53,0) | G13: =IF(6>='Параметры'!B52,'Параметры'!B53,0) | H13: =IF(7>='Параметры'!B52,'Параметры'!B53,0) | I13: =IF(8>='Параметры'!B52,'Параметры'!B53,0) | J13: =IF(9>='Параметры'!B52,'Параметры'!B53,0) | K13: =IF(10>='Параметры'!B52,'Параметры'!B53,0) | L13: =IF(11>='Параметры'!B52,'Параметры'!B53,0) | M13: =IF(12>='Параметры'!B52,'Параметры'!B53,0) | N13: =IF(13>='Параметры'!B52,'Параметры'!B53,0) | O13: =IF(14>='Параметры'!B52,'Параметры'!B53,0) | P13: =IF(15>='Параметры'!B52,'Параметры'!B53,0) | Q13: =IF(16>='Параметры'!B52,'Параметры'!B53,0) | R13: =IF(17>='Параметры'!B52,'Параметры'!B53,0) | S13: =IF(18>='Параметры'!B52,'Параметры'!B53,0) | T13: =IF(19>='Параметры'!B52,'Параметры'!B53,0) | U13: =IF(20>='Параметры'!B52,'Параметры'!B53,0) | V13: =IF(21>='Параметры'!B52,'Параметры'!B53,0) | W13: =IF(22>='Параметры'!B52,'Параметры'!B53,0) | X13: =IF(23>='Параметры'!B52,'Параметры'!B53,0) | Y13: =IF(24>='Параметры'!B52,'Параметры'!B53,0)
A14: Партнёрская экосистема | B14: =IF(1>='Параметры'!B54,'Параметры'!B55,0) | C14: =IF(2>='Параметры'!B54,'Параметры'!B55,0) | D14: =IF(3>='Параметры'!B54,'Параметры'!B55,0) | E14: =IF(4>='Параметры'!B54,'Параметры'!B55,0) | F14: =IF(5>='Параметры'!B54,'Параметры'!B55,0) | G14: =IF(6>='Параметры'!B54,'Параметры'!B55,0) | H14: =IF(7>='Параметры'!B54,'Параметры'!B55,0) | I14: =IF(8>='Параметры'!B54,'Параметры'!B55,0) | J14: =IF(9>='Параметры'!B54,'Параметры'!B55,0) | K14: =IF(10>='Параметры'!B54,'Параметры'!B55,0) | L14: =IF(11>='Параметры'!B54,'Параметры'!B55,0) | M14: =IF(12>='Параметры'!B54,'Параметры'!B55,0) | N14: =IF(13>='Параметры'!B54,'Параметры'!B55,0) | O14: =IF(14>='Параметры'!B54,'Параметры'!B55,0) | P14: =IF(15>='Параметры'!B54,'Параметры'!B55,0) | Q14: =IF(16>='Параметры'!B54,'Параметры'!B55,0) | R14: =IF(17>='Параметры'!B54,'Параметры'!B55,0) | S14: =IF(18>='Параметры'!B54,'Параметры'!B55,0) | T14: =IF(19>='Параметры'!B54,'Параметры'!B55,0) | U14: =IF(20>='Параметры'!B54,'Параметры'!B55,0) | V14: =IF(21>='Параметры'!B54,'Параметры'!B55,0) | W14: =IF(22>='Параметры'!B54,'Параметры'!B55,0) | X14: =IF(23>='Параметры'!B54,'Параметры'!B55,0) | Y14: =IF(24>='Параметры'!B54,'Параметры'!B55,0)
A15: ИИ-помощник | B15: =IF(1>='Параметры'!B56,'Параметры'!B57,0) | C15: =IF(2>='Параметры'!B56,'Параметры'!B57,0) | D15: =IF(3>='Параметры'!B56,'Параметры'!B57,0) | E15: =IF(4>='Параметры'!B56,'Параметры'!B57,0) | F15: =IF(5>='Параметры'!B56,'Параметры'!B57,0) | G15: =IF(6>='Параметры'!B56,'Параметры'!B57,0) | H15: =IF(7>='Параметры'!B56,'Параметры'!B57,0) | I15: =IF(8>='Параметры'!B56,'Параметры'!B57,0) | J15: =IF(9>='Параметры'!B56,'Параметры'!B57,0) | K15: =IF(10>='Параметры'!B56,'Параметры'!B57,0) | L15: =IF(11>='Параметры'!B56,'Параметры'!B57,0) | M15: =IF(12>='Параметры'!B56,'Параметры'!B57,0) | N15: =IF(13>='Параметры'!B56,'Параметры'!B57,0) | O15: =IF(14>='Параметры'!B56,'Параметры'!B57,0) | P15: =IF(15>='Параметры'!B56,'Параметры'!B57,0) | Q15: =IF(16>='Параметры'!B56,'Параметры'!B57,0) | R15: =IF(17>='Параметры'!B56,'Параметры'!B57,0) | S15: =IF(18>='Параметры'!B56,'Параметры'!B57,0) | T15: =IF(19>='Параметры'!B56,'Параметры'!B57,0) | U15: =IF(20>='Параметры'!B56,'Параметры'!B57,0) | V15: =IF(21>='Параметры'!B56,'Параметры'!B57,0) | W15: =IF(22>='Параметры'!B56,'Параметры'!B57,0) | X15: =IF(23>='Параметры'!B56,'Параметры'!B57,0) | Y15: =IF(24>='Параметры'!B56,'Параметры'!B57,0)
A16: Сообщества | B16: =IF(1>='Параметры'!B58,'Параметры'!B59,0) | C16: =IF(2>='Параметры'!B58,'Параметры'!B59,0) | D16: =IF(3>='Параметры'!B58,'Параметры'!B59,0) | E16: =IF(4>='Параметры'!B58,'Параметры'!B59,0) | F16: =IF(5>='Параметры'!B58,'Параметры'!B59,0) | G16: =IF(6>='Параметры'!B58,'Параметры'!B59,0) | H16: =IF(7>='Параметры'!B58,'Параметры'!B59,0) | I16: =IF(8>='Параметры'!B58,'Параметры'!B59,0) | J16: =IF(9>='Параметры'!B58,'Параметры'!B59,0) | K16: =IF(10>='Параметры'!B58,'Параметры'!B59,0) | L16: =IF(11>='Параметры'!B58,'Параметры'!B59,0) | M16: =IF(12>='Параметры'!B58,'Параметры'!B59,0) | N16: =IF(13>='Параметры'!B58,'Параметры'!B59,0) | O16: =IF(14>='Параметры'!B58,'Параметры'!B59,0) | P16: =IF(15>='Параметры'!B58,'Параметры'!B59,0) | Q16: =IF(16>='Параметры'!B58,'Параметры'!B59,0) | R16: =IF(17>='Параметры'!B58,'Параметры'!B59,0) | S16: =IF(18>='Параметры'!B58,'Параметры'!B59,0) | T16: =IF(19>='Параметры'!B58,'Параметры'!B59,0) | U16: =IF(20>='Параметры'!B58,'Параметры'!B59,0) | V16: =IF(21>='Параметры'!B58,'Параметры'!B59,0) | W16: =IF(22>='Параметры'!B58,'Параметры'!B59,0) | X16: =IF(23>='Параметры'!B58,'Параметры'!B59,0) | Y16: =IF(24>='Параметры'!B58,'Параметры'!B59,0)
A17: ИТОГО выручка | B17: =SUM(B11:B16) | C17: =SUM(C11:C16) | D17: =SUM(D11:D16) | E17: =SUM(E11:E16) | F17: =SUM(F11:F16) | G17: =SUM(G11:G16) | H17: =SUM(H11:H16) | I17: =SUM(I11:I16) | ... Y17: =SUM(Y11:Y16)
A19: РАСХОДЫ
A20: Разработка | B20: =IF(1<=6,'Параметры'!B33,IF(1<=12,'Параметры'!B34,'Параметры'!B35)) | C20: =IF(2<=6,'Параметры'!B33,IF(2<=12,'Параметры'!B34,'Параметры'!B35)) | D20: =IF(3<=6,'Параметры'!B33,IF(3<=12,'Параметры'!B34,'Параметры'!B35)) | E20: =IF(4<=6,'Параметры'!B33,IF(4<=12,'Параметры'!B34,'Параметры'!B35)) | F20: =IF(5<=6,'Параметры'!B33,IF(5<=12,'Параметры'!B34,'Параметры'!B35)) | G20: =IF(6<=6,'Параметры'!B33,IF(6<=12,'Параметры'!B34,'Параметры'!B35)) | H20: =IF(7<=6,'Параметры'!B33,IF(7<=12,'Параметры'!B34,'Параметры'!B35)) | I20: =IF(8<=6,'Параметры'!B33,IF(8<=12,'Параметры'!B34,'Параметры'!B35)) | J20: =IF(9<=6,'Параметры'!B33,IF(9<=12,'Параметры'!B34,'Параметры'!B35)) | K20: =IF(10<=6,'Параметры'!B33,IF(10<=12,'Параметры'!B34,'Параметры'!B35)) | L20: =IF(11<=6,'Параметры'!B33,IF(11<=12,'Параметры'!B34,'Параметры'!B35)) | M20: =IF(12<=6,'Параметры'!B33,IF(12<=12,'Параметры'!B34,'Параметры'!B35)) | N20: =IF(13<=6,'Параметры'!B33,IF(13<=12,'Параметры'!B34,'Параметры'!B35)) | O20: =IF(14<=6,'Параметры'!B33,IF(14<=12,'Параметры'!B34,'Параметры'!B35)) | P20: =IF(15<=6,'Параметры'!B33,IF(15<=12,'Параметры'!B34,'Параметры'!B35)) | Q20: =IF(16<=6,'Параметры'!B33,IF(16<=12,'Параметры'!B34,'Параметры'!B35)) | R20: =IF(17<=6,'Параметры'!B33,IF(17<=12,'Параметры'!B34,'Параметры'!B35)) | S20: =IF(18<=6,'Параметры'!B33,IF(18<=12,'Параметры'!B34,'Параметры'!B35)) | T20: =IF(19<=6,'Параметры'!B33,IF(19<=12,'Параметры'!B34,'Параметры'!B35)) | U20: =IF(20<=6,'Параметры'!B33,IF(20<=12,'Параметры'!B34,'Параметры'!B35)) | V20: =IF(21<=6,'Параметры'!B33,IF(21<=12,'Параметры'!B34,'Параметры'!B35)) | W20: =IF(22<=6,'Параметры'!B33,IF(22<=12,'Параметры'!B34,'Параметры'!B35)) | X20: =IF(23<=6,'Параметры'!B33,IF(23<=12,'Параметры'!B34,'Параметры'!B35)) | Y20: =IF(24<=6,'Параметры'!B33,IF(24<=12,'Параметры'!B34,'Параметры'!B35))
A21: Маркетинг | B21: =IF(1<=6,'Параметры'!B36,IF(1<=12,'Параметры'!B37,'Параметры'!B38)) | C21: =IF(2<=6,'Параметры'!B36,IF(2<=12,'Параметры'!B37,'Параметры'!B38)) | D21: =IF(3<=6,'Параметры'!B36,IF(3<=12,'Параметры'!B37,'Параметры'!B38)) | E21: =IF(4<=6,'Параметры'!B36,IF(4<=12,'Параметры'!B37,'Параметры'!B38)) | F21: =IF(5<=6,'Параметры'!B36,IF(5<=12,'Параметры'!B37,'Параметры'!B38)) | G21: =IF(6<=6,'Параметры'!B36,IF(6<=12,'Параметры'!B37,'Параметры'!B38)) | H21: =IF(7<=6,'Параметры'!B36,IF(7<=12,'Параметры'!B37,'Параметры'!B38)) | I21: =IF(8<=6,'Параметры'!B36,IF(8<=12,'Параметры'!B37,'Параметры'!B38)) | J21: =IF(9<=6,'Параметры'!B36,IF(9<=12,'Параметры'!B37,'Параметры'!B38)) | K21: =IF(10<=6,'Параметры'!B36,IF(10<=12,'Параметры'!B37,'Параметры'!B38)) | L21: =IF(11<=6,'Параметры'!B36,IF(11<=12,'Параметры'!B37,'Параметры'!B38)) | M21: =IF(12<=6,'Параметры'!B36,IF(12<=12,'Параметры'!B37,'Параметры'!B38)) | N21: =IF(13<=6,'Параметры'!B36,IF(13<=12,'Параметры'!B37,'Параметры'!B38)) | O21: =IF(14<=6,'Параметры'!B36,IF(14<=12,'Параметры'!B37,'Параметры'!B38)) | P21: =IF(15<=6,'Параметры'!B36,IF(15<=12,'Параметры'!B37,'Параметры'!B38)) | Q21: =IF(16<=6,'Параметры'!B36,IF(16<=12,'Параметры'!B37,'Параметры'!B38)) | R21: =IF(17<=6,'Параметры'!B36,IF(17<=12,'Параметры'!B37,'Параметры'!B38)) | S21: =IF(18<=6,'Параметры'!B36,IF(18<=12,'Параметры'!B37,'Параметры'!B38)) | T21: =IF(19<=6,'Параметры'!B36,IF(19<=12,'Параметры'!B37,'Параметры'!B38)) | U21: =IF(20<=6,'Параметры'!B36,IF(20<=12,'Параметры'!B37,'Параметры'!B38)) | V21: =IF(21<=6,'Параметры'!B36,IF(21<=12,'Параметры'!B37,'Параметры'!B38)) | W21: =IF(22<=6,'Параметры'!B36,IF(22<=12,'Параметры'!B37,'Параметры'!B38)) | X21: =IF(23<=6,'Параметры'!B36,IF(23<=12,'Параметры'!B37,'Параметры'!B38)) | Y21: =IF(24<=6,'Параметры'!B36,IF(24<=12,'Параметры'!B37,'Параметры'!B38))
A22: Инфраструктура РФ | B22: =IF(1<=6,'Параметры'!B39,IF(1<=12,'Параметры'!B40,'Параметры'!B41)) | C22: =IF(2<=6,'Параметры'!B39,IF(2<=12,'Параметры'!B40,'Параметры'!B41)) | D22: =IF(3<=6,'Параметры'!B39,IF(3<=12,'Параметры'!B40,'Параметры'!B41)) | E22: =IF(4<=6,'Параметры'!B39,IF(4<=12,'Параметры'!B40,'Параметры'!B41)) | F22: =IF(5<=6,'Параметры'!B39,IF(5<=12,'Параметры'!B40,'Параметры'!B41)) | G22: =IF(6<=6,'Параметры'!B39,IF(6<=12,'Параметры'!B40,'Параметры'!B41)) | H22: =IF(7<=6,'Параметры'!B39,IF(7<=12,'Параметры'!B40,'Параметры'!B41)) | I22: =IF(8<=6,'Параметры'!B39,IF(8<=12,'Параметры'!B40,'Параметры'!B41)) | J22: =IF(9<=6,'Параметры'!B39,IF(9<=12,'Параметры'!B40,'Параметры'!B41)) | K22: =IF(10<=6,'Параметры'!B39,IF(10<=12,'Параметры'!B40,'Параметры'!B41)) | L22: =IF(11<=6,'Параметры'!B39,IF(11<=12,'Параметры'!B40,'Параметры'!B41)) | M22: =IF(12<=6,'Параметры'!B39,IF(12<=12,'Параметры'!B40,'Параметры'!B41)) | N22: =IF(13<=6,'Параметры'!B39,IF(13<=12,'Параметры'!B40,'Параметры'!B41)) | O22: =IF(14<=6,'Параметры'!B39,IF(14<=12,'Параметры'!B40,'Параметры'!B41)) | P22: =IF(15<=6,'Параметры'!B39,IF(15<=12,'Параметры'!B40,'Параметры'!B41)) | Q22: =IF(16<=6,'Параметры'!B39,IF(16<=12,'Параметры'!B40,'Параметры'!B41)) | R22: =IF(17<=6,'Параметры'!B39,IF(17<=12,'Параметры'!B40,'Параметры'!B41)) | S22: =IF(18<=6,'Параметры'!B39,IF(18<=12,'Параметры'!B40,'Параметры'!B41)) | T22: =IF(19<=6,'Параметры'!B39,IF(19<=12,'Параметры'!B40,'Параметры'!B41)) | U22: =IF(20<=6,'Параметры'!B39,IF(20<=12,'Параметры'!B40,'Параметры'!B41)) | V22: =IF(21<=6,'Параметры'!B39,IF(21<=12,'Параметры'!B40,'Параметры'!B41)) | W22: =IF(22<=6,'Параметры'!B39,IF(22<=12,'Параметры'!B40,'Параметры'!B41)) | X22: =IF(23<=6,'Параметры'!B39,IF(23<=12,'Параметры'!B40,'Параметры'!B41)) | Y22: =IF(24<=6,'Параметры'!B39,IF(24<=12,'Параметры'!B40,'Параметры'!B41))
A23: Контент | B23: =IF(1<=6,'Параметры'!B42,IF(1<=12,'Параметры'!B43,'Параметры'!B44)) | C23: =IF(2<=6,'Параметры'!B42,IF(2<=12,'Параметры'!B43,'Параметры'!B44)) | D23: =IF(3<=6,'Параметры'!B42,IF(3<=12,'Параметры'!B43,'Параметры'!B44)) | E23: =IF(4<=6,'Параметры'!B42,IF(4<=12,'Параметры'!B43,'Параметры'!B44)) | F23: =IF(5<=6,'Параметры'!B42,IF(5<=12,'Параметры'!B43,'Параметры'!B44)) | G23: =IF(6<=6,'Параметры'!B42,IF(6<=12,'Параметры'!B43,'Параметры'!B44)) | H23: =IF(7<=6,'Параметры'!B42,IF(7<=12,'Параметры'!B43,'Параметры'!B44)) | I23: =IF(8<=6,'Параметры'!B42,IF(8<=12,'Параметры'!B43,'Параметры'!B44)) | J23: =IF(9<=6,'Параметры'!B42,IF(9<=12,'Параметры'!B43,'Параметры'!B44)) | K23: =IF(10<=6,'Параметры'!B42,IF(10<=12,'Параметры'!B43,'Параметры'!B44)) | L23: =IF(11<=6,'Параметры'!B42,IF(11<=12,'Параметры'!B43,'Параметры'!B44)) | M23: =IF(12<=6,'Параметры'!B42,IF(12<=12,'Параметры'!B43,'Параметры'!B44)) | N23: =IF(13<=6,'Параметры'!B42,IF(13<=12,'Параметры'!B43,'Параметры'!B44)) | O23: =IF(14<=6,'Параметры'!B42,IF(14<=12,'Параметры'!B43,'Параметры'!B44)) | P23: =IF(15<=6,'Параметры'!B42,IF(15<=12,'Параметры'!B43,'Параметры'!B44)) | Q23: =IF(16<=6,'Параметры'!B42,IF(16<=12,'Параметры'!B43,'Параметры'!B44)) | R23: =IF(17<=6,'Параметры'!B42,IF(17<=12,'Параметры'!B43,'Параметры'!B44)) | S23: =IF(18<=6,'Параметры'!B42,IF(18<=12,'Параметры'!B43,'Параметры'!B44)) | T23: =IF(19<=6,'Параметры'!B42,IF(19<=12,'Параметры'!B43,'Параметры'!B44)) | U23: =IF(20<=6,'Параметры'!B42,IF(20<=12,'Параметры'!B43,'Параметры'!B44)) | V23: =IF(21<=6,'Параметры'!B42,IF(21<=12,'Параметры'!B43,'Параметры'!B44)) | W23: =IF(22<=6,'Параметры'!B42,IF(22<=12,'Параметры'!B43,'Параметры'!B44)) | X23: =IF(23<=6,'Параметры'!B42,IF(23<=12,'Параметры'!B43,'Параметры'!B44)) | Y23: =IF(24<=6,'Параметры'!B42,IF(24<=12,'Параметры'!B43,'Параметры'!B44))
A24: App Store комиссия | B24: =ROUND(B11*'Параметры'!B45/100*'Параметры'!B46/100,0) | C24: =ROUND(C11*'Параметры'!B45/100*'Параметры'!B46/100,0) | D24: =ROUND(D11*'Параметры'!B45/100*'Параметры'!B46/100,0) | E24: =ROUND(E11*'Параметры'!B45/100*'Параметры'!B46/100,0) | F24: =ROUND(F11*'Параметры'!B45/100*'Параметры'!B46/100,0) | G24: =ROUND(G11*'Параметры'!B45/100*'Параметры'!B46/100,0) | H24: =ROUND(H11*'Параметры'!B45/100*'Параметры'!B46/100,0) | I24: =ROUND(I11*'Параметры'!B45/100*'Параметры'!B46/100,0) | J24: =ROUND(J11*'Параметры'!B45/100*'Параметры'!B46/100,0) | K24: =ROUND(K11*'Параметры'!B45/100*'Параметры'!B46/100,0) | L24: =ROUND(L11*'Параметры'!B45/100*'Параметры'!B46/100,0) | M24: =ROUND(M11*'Параметры'!B45/100*'Параметры'!B46/100,0) | N24: =ROUND(N11*'Параметры'!B45/100*'Параметры'!B46/100,0) | O24: =ROUND(O11*'Параметры'!B45/100*'Параметры'!B46/100,0) | P24: =ROUND(P11*'Параметры'!B45/100*'Параметры'!B46/100,0) | Q24: =ROUND(Q11*'Параметры'!B45/100*'Параметры'!B46/100,0) | R24: =ROUND(R11*'Параметры'!B45/100*'Параметры'!B46/100,0) | S24: =ROUND(S11*'Параметры'!B45/100*'Параметры'!B46/100,0) | T24: =ROUND(T11*'Параметры'!B45/100*'Параметры'!B46/100,0) | U24: =ROUND(U11*'Параметры'!B45/100*'Параметры'!B46/100,0) | V24: =ROUND(V11*'Параметры'!B45/100*'Параметры'!B46/100,0) | W24: =ROUND(W11*'Параметры'!B45/100*'Параметры'!B46/100,0) | X24: =ROUND(X11*'Параметры'!B45/100*'Параметры'!B46/100,0) | Y24: =ROUND(Y11*'Параметры'!B45/100*'Параметры'!B46/100,0)
A25: Telegram-бот | B25: =IF(1>=3,'Параметры'!B47,0) | C25: =IF(2>=3,'Параметры'!B47,0) | D25: =IF(3>=3,'Параметры'!B47,0) | E25: =IF(4>=3,'Параметры'!B47,0) | F25: =IF(5>=3,'Параметры'!B47,0) | G25: =IF(6>=3,'Параметры'!B47,0) | H25: =IF(7>=3,'Параметры'!B47,0) | I25: =IF(8>=3,'Параметры'!B47,0) | J25: =IF(9>=3,'Параметры'!B47,0) | K25: =IF(10>=3,'Параметры'!B47,0) | L25: =IF(11>=3,'Параметры'!B47,0) | M25: =IF(12>=3,'Параметры'!B47,0) | N25: =IF(13>=3,'Параметры'!B47,0) | O25: =IF(14>=3,'Параметры'!B47,0) | P25: =IF(15>=3,'Параметры'!B47,0) | Q25: =IF(16>=3,'Параметры'!B47,0) | R25: =IF(17>=3,'Параметры'!B47,0) | S25: =IF(18>=3,'Параметры'!B47,0) | T25: =IF(19>=3,'Параметры'!B47,0) | U25: =IF(20>=3,'Параметры'!B47,0) | V25: =IF(21>=3,'Параметры'!B47,0) | W25: =IF(22>=3,'Параметры'!B47,0) | X25: =IF(23>=3,'Параметры'!B47,0) | Y25: =IF(24>=3,'Параметры'!B47,0)
A26: ИТОГО расходы | B26: =SUM(B20:B25) | C26: =SUM(C20:C25) | D26: =SUM(D20:D25) | E26: =SUM(E20:E25) | F26: =SUM(F20:F25) | G26: =SUM(G20:G25) | H26: =SUM(H20:H25) | I26: =SUM(I20:I25) | ... Y26: =SUM(Y20:Y25)
A28: P&L месячный | B28: =B17-B26 | C28: =C17-C26 | D28: =D17-D26 | E28: =E17-E26 | F28: =F17-F26 | G28: =G17-G26 | H28: =H17-H26 | I28: =I17-I26 | ... Y28: =Y17-Y26
A29: P&L накопленный | B29: =B28-'Параметры'!B6 | C29: =B29+C28 | D29: =C29+D28 | E29: =D29+E28 | F29: =E29+F28 | G29: =F29+G28 | H29: =G29+H28 | I29: =H29+I28 | J29: =I29+J28 | ... Y29: =X29+Y28

Sheet Unit-экономика
A1: Unit-экономика EVA
A3: Метрика | B3: Значение | C3: Комментарий
A4: ARPU средний/мес | B4: ='Параметры'!B10*(1-'Параметры'!B12/100)+'Параметры'!B11/12*'Параметры'!B12/100 | C4: Микс тарифов
A5: CAC | B5: ='Параметры'!B15
A6: Churn месячный | B6: ='Параметры'!B23/100
A7: Срок жизни, мес | B7: =1/('Параметры'!B23/100) | C7: 1/churn
A8: LTV | B8: =B4*B7 | C8: ARPU * срок жизни
A9: LTV / CAC | B9: =B8/B5 | C9: Целевой: >3x
A10: Payback, мес | B10: =B5/B4 | C10: CAC / ARPU

Sheet Сводка
A1: Сводные показатели
A3: Инвестиции | B3: ='Параметры'!B6
A4: Пользователей мес 24 | B4: ='P&L помесячный'!Y6
A5: EVA+ подписчиков мес 24 | B5: ='P&L помесячный'!Y7
A6: Выручка мес 24 | B6: ='P&L помесячный'!Y17
A7: P&L накопл. мес 24 | B7: ='P&L помесячный'!Y29
A8: ROI мес 24 | B8: ='P&L помесячный'!Y29/'Параметры'!B6
A9: LTV / CAC | B9: ='Unit-экономика'!B9
